Workbook

Sheet Cover
B3: ETERNAL LIMITED
B4: (formerly Zomato Limited)
B5: DCF Valuation Report — Three-Case Scenario Framework
B7: NSE: ETERNAL | E7: ="Valuation Date: "&TEXT(TODAY(),"d-mmm-yyyy") -> Valuation Date: 6-May-2026
B8: ="Decision rule: BUY if weighted upside ≥ "&TEXT(I12,"0.0%")&" • HOLD if 0% to "&TEXT(I12,"0.0%")&" • REDUCE if "&TEXT(I14,"0.0%")&" to 0% • SELL if < "&TEXT(I14,"0.0%") -> Decision rule: BUY if weighted upside ≥ 15.0% • HOLD if 0% to 15.0% • REDUCE if -15.0% to 0% • SELL if < -15.0%
B10: INVESTMENT RECOMMENDATION | H10: Decision Thresholds
B11: CURRENT PRICE | C11: IMPLIED PRICE (Active Case) | D11: PROB-WEIGHTED PRICE | E11: RECOMMENDATION | H11: Metric | I11: Threshold
B12: =Assumptions!F7 -> 251 | C12: =DCF!F54 -> 287.17054 | D12: =Summary!C43 -> 141.82559 | E12: =IF(Summary!F43>=I12,"BUY",IF(Summary!F43>=I13,"HOLD",IF(Summary!F43>=I14,"REDUCE","SELL"))) -> SELL | H12: BUY threshold | I12: 0.15
B13: NSE close (input) | C13: ="vs current: "&TEXT(DCF!F56,"+0.0%;-0.0%") -> vs current: +14.4% | D13: ="vs current: "&TEXT(Summary!F43,"+0.0%;-0.0%") -> vs current: -43.5% | E13: ="Weighted upside: "&TEXT(Summary!F43,"+0.0%;-0.0%") -> Weighted upside: -43.5% | H13: HOLD threshold | I13: 0
H14: SELL threshold | I14: -0.15
B16: COMPANY SNAPSHOT
B17: Company Name | C17: Eternal Limited (formerly Zomato Limited) | D17: Headquarters | E17: Gurugram, Haryana, India
B18: Listing | C18: NSE & BSE | D18: Ticker | E18: ETERNAL (NSE.ETERNAL)
B19: Founded | C19: 2008 | D19: Founders | E19: Deepinder Goyal & Pankaj Chaddah
B20: Industry | C20: Internet — Food, Quick Commerce & Lifestyle | D20: Sector | E20: Consumer Internet
B21: Rebrand Date | C21: 9 April 2025 (Zomato → Eternal) | D21: Currency | E21: INR (₹), figures in crores
B22: Reporting Period | C22: FY22 — FY25 (historicals); FY26E — FY35E (forecast) | D22: Status | E22: Listed Public Limited
B24: BUSINESS SEGMENTS
B25: Segment | C25: Description | D25: Latest NOV (Q4 FY26) | E25: Strategic Status
B26: Food Delivery | C26: Restaurant marketplace & delivery (Zomato app); core consumer business with 25.4M MTC | D26: ₹9,760 Cr (+19% YoY) | E26: Profitable; ~5.5% adj. EBITDA margin
B27: Quick Commerce (Blinkit) | C27: Instant grocery via 2,243+ dark stores; fastest-growing vertical, transitioning to 1P inventory model | D27: ₹14,390 Cr (+121% YoY) | E27: Adj. EBITDA-positive (Q3 FY26)
B28: Hyperpure (B2B) | C28: B2B fresh-ingredient supply chain to restaurants & food businesses; strategic ecosystem moat | D28: ₹980 Cr | E28: Adj. EBITDA-positive (Q3 FY26)
B29: Going Out | C29: Events, ticketing, experiences, District Pass loyalty product; offline lifestyle play | D29: +46% YoY (NOV) | E29: Investment phase; loss ~₹81 Cr
B31: VALUATION APPROACH
B32: Methodology | C32: 10-year FCFF DCF with Gordon-growth terminal value
B33: Forecast Horizon | C33: FY26E — FY35E explicit forecast period; perpetuity thereafter
B34: Cost of Capital | C34: WACC build via CAPM (Rf + β × ERP); blended with after-tax cost of debt at target capital structure
B35: Scenario Framework | C35: Base / Optimistic / Pessimistic — each with case-specific WACC, segment growth, margins, & terminal growth
B37: SCENARIO OUTPUTS — IMPLIED EQUITY VALUE PER SHARE
B38: Scenario | C38: WACC | D38: Implied / share | E38: Upside / (Downside)
B39: Base Case | C39: =Assumptions!T24 -> 0.13021171 | D39: =Scenarios!D52 -> 87.613016 | E39: =Scenarios!D54 -> -0.65094416
B40: Optimistic Case | C40: =Assumptions!U24 -> 0.12017267 | D40: =Scenarios!D103 -> 287.17054 | E40: =Scenarios!D105 -> 0.14410573
B41: Pessimistic Case | C41: =Assumptions!V24 -> 0.14359709 | D41: =Scenarios!D154 -> 25.0828 | E41: =Scenarios!D156 -> -0.90006853
B43: HOW TO NAVIGATE THIS MODEL
B44: 1. Summary | C44: Executive summary with active scenario card, full 3-case comparison & probability-weighted view
B45: 2. Assumptions | C45: All model inputs — WACC build, terminal value, segment drivers; toggle Summary!F5 to switch scenario
B46: 3. Scenarios | C46: Three parallel mini-DCFs (Base / Optimistic / Pessimistic) running simultaneously
B47: 4. DCF | C47: Main DCF tied to active scenario; FCFF derivation, discounted cash flows, EV bridge
B48: 5. Sensitivity | C48: 2D sensitivity tables — WACC × terminal growth and WACC × terminal margin
B49: 6. Historicals | C49: Balance Sheet, P&L, Cash Flow, Equity statements (FY22-FY25) extracted from annual reports
...

Sheet Summary
A1: Eternal Limited (formerly Zomato Limited) — DCF Valuation Summary
A2: Three-case scenario DCF — base / optimistic / pessimistic. All values in INR crores unless stated. Valuation date: 5-May-2026.
A4: ACTIVE SCENARIO (live link to toggle)
A5: Active case | B5: =Assumptions!T7 -> Optimistic Case | D5: Toggle (1=Base / 2=Opt / 3=Pess): | F5: 1
A6: Active implied / share | B6: =DCF!F54 -> 287.17054 | D6: Active upside / (downside) | F6: =DCF!F56 -> 0.14410573
A7: To switch scenario, change F5 above (1=Base / 2=Optimistic / 3=Pessimistic). DCF, Sensitivity, Assumptions, and Summary auto-recompute.
A8: SCENARIO COMPARISON
A9: Metric | B9: Unit | C9: Base | D9: Optimistic | E9: Pessimistic | F9: Opt – Pess range
A10: Cost of capital & terminal
A11: WACC | B11: % | C11: =Assumptions!T24 -> 0.13021171 | D11: =Assumptions!U24 -> 0.12017267 | E11: =Assumptions!V24 -> 0.14359709 | F11: =D11-E11 -> -0.023424424
A12: Beta (levered) | B12: x | C12: =Assumptions!T17 -> 0.9 | D12: =Assumptions!U17 -> 0.75 | E12: =Assumptions!V17 -> 1.1 | F12: =D12-E12 -> -0.35
A13: Terminal growth (perpetual) | B13: % | C13: =Assumptions!T28 -> 0.05 | D13: =Assumptions!U28 -> 0.06 | E13: =Assumptions!V28 -> 0.04 | F13: =D13-E13 -> 0.02
A15: Revenue trajectory
A16: FY26E Total Revenue | B16: ₹ Cr | C16: =Scenarios!D14 -> 32235.8 | D16: =Scenarios!D65 -> 34449.2 | E16: =Scenarios!D116 -> 29713.32 | F16: =D16-E16 -> 4735.88
A17: FY30E Total Revenue | B17: ₹ Cr | C17: =Scenarios!H14 -> 111899.78 | D17: =Scenarios!H65 -> 158585.8 | E17: =Scenarios!H116 -> 76077.748 | F17: =D17-E17 -> 82508.054
A18: FY35E Total Revenue | B18: ₹ Cr | C18: =Scenarios!M14 -> 226238.24 | D18: =Scenarios!M65 -> 413523.93 | E18: =Scenarios!M116 -> 119326.63 | F18: =D18-E18 -> 294197.3
A19: Revenue CAGR FY25–FY35 | B19: % | C19: =(Scenarios!M14/Scenarios!C14)^(1/10)-1 -> 0.27300208 | D19: =(Scenarios!M65/Scenarios!C65)^(1/10)-1 -> 0.35214285 | E19: =(Scenarios!M116/Scenarios!C116)^(1/10)-1 -> 0.19411527 | F19: =D19-E19 -> 0.15802759
A21: Steady-state profitability (FY35E)
A22: Adj. EBITDA margin | B22: % | C22: =Scenarios!M24 -> 0.13366474 | D22: =Scenarios!M75 -> 0.16223003 | E22: =Scenarios!M126 -> 0.10399943 | F22: =D22-E22 -> 0.058230604
A23: EBIT margin | B23: % | C23: =Scenarios!M30 -> 0.083664739 | D23: =Scenarios!M81 -> 0.11623003 | E23: =Scenarios!M132 -> 0.045999427 | F23: =D23-E23 -> 0.070230604
A24: FCFF margin | B24: % | C24: =Scenarios!M37 -> 0.058140812 | D24: =Scenarios!M88 -> 0.085309833 | E24: =Scenarios!M139 -> 0.031138673 | F24: =D24-E24 -> 0.05417116
A25: FY35E FCFF | B25: ₹ Cr | C25: =Scenarios!M36 -> 13153.675 | D25: =Scenarios!M87 -> 35277.657 | E25: =Scenarios!M138 -> 3715.6729 | F25: =D25-E25 -> 31561.984
A27: Valuation bridge
A28: Sum of PV of explicit FCFF | B28: ₹ Cr | C28: =Scenarios!D43 -> 17973.636 | D28: =Scenarios!D94 -> 58699.654 | E28: =Scenarios!D145 -> -644.45088 | F28: =D28-E28 -> 59344.105
A29: PV of Terminal Value | B29: ₹ Cr | C29: =Scenarios!D46 -> 50629.149 | D29: =Scenarios!D97 -> 199782.11 | E29: =Scenarios!D148 -> 9749.7352 | F29: =D29-E29 -> 190032.38
A30: Enterprise Value | B30: ₹ Cr | C30: =Scenarios!D47 -> 68602.785 | D30: =Scenarios!D98 -> 258481.77 | E30: =Scenarios!D149 -> 9105.2844 | F30: =D30-E30 -> 249376.48
A31: Less: Total debt | B31: ₹ Cr | C31: =Scenarios!D48 -> -2045 | D31: =Scenarios!D99 -> -2045 | E31: =Scenarios!D150 -> -2045 | F31: =D31-E31 -> 0
A32: Plus: Cash & investments | B32: ₹ Cr | C32: =Scenarios!D49 -> 16806 | D32: =Scenarios!D100 -> 16806 | E32: =Scenarios!D151 -> 16806 | F32: =D32-E32 -> 0
A33: Equity Value | B33: ₹ Cr | C33: =Scenarios!D50 -> 83363.785 | D33: =Scenarios!D101 -> 273242.77 | E33: =Scenarios!D152 -> 23866.284 | F33: =D33-E33 -> 249376.48
A35: Per share
A36: Shares outstanding | B36: cr | C36: =Scenarios!D51 -> 951.5 | D36: =Scenarios!D102 -> 951.5 | E36: =Scenarios!D153 -> 951.5 | F36: =D36-E36 -> 0
A37: Implied per share value | B37: ₹ | C37: =Scenarios!D52 -> 87.613016 | D37: =Scenarios!D103 -> 287.17054 | E37: =Scenarios!D154 -> 25.0828 | F37: =D37-E37 -> 262.08774
A38: Current share price | B38: ₹ | C38: =Scenarios!D53 -> 251 | D38: =Scenarios!D104 -> 251 | E38: =Scenarios!D155 -> 251 | F38: =D38-E38 -> 0
A39: Implied upside / (downside) | B39: % | C39: =Scenarios!D54 -> -0.65094416 | D39: =Scenarios!D105 -> 0.14410573 | E39: =Scenarios!D156 -> -0.90006853 | F39: =D39-E39 -> 1.0441743
A41: INVESTMENT VIEW
A42: Probability-weighted equity value (40% Base / 35% Opt / 25% Pess) | B42: ₹ Cr | C42: =B45*Scenarios!D50+D45*Scenarios!D101+F45*Scenarios!D152 -> 134947.05
A43: Probability-weighted implied per share | B43: ₹ | C43: =C42/Assumptions!F8 -> 141.82559 | D43: vs current price | E43: =Assumptions!F7 -> 251 | F43: =C43/E43-1 -> -0.43495779
A44: Probability weights are illustrative and editable here:
A45: Base weight | B45: 0.4 | C45: Optimistic weight | D45: 0.35 | E45: Pessimistic weight | F45: 0.25
A46: Sum check (must = 100%) | B46: =B45+D45+F45 -> 1 | C46: =IF(ABS(B46-1)<0.001,"OK","Check weights") -> OK
...

Sheet Assumptions
A1: Eternal Limited (formerly Zomato Limited) — DCF Valuation Assumptions
A2: Valuation date: 5 May 2026. All financials in INR crores unless stated. Forecast period: FY26E–FY35E + Terminal. | S2: =T7 -> Optimistic Case
A4: Particulars | B4: Unit | C4: FY22A | D4: FY23A | E4: FY24A | F4: FY25A | G4: FY26E | H4: FY27E | I4: FY28E | J4: FY29E | K4: FY30E | L4: FY31E | M4: FY32E | N4: FY33E | O4: FY34E | P4: FY35E | Q4: Terminal | S4: Scenario Control
A5: MARKET & CAPITAL STRUCTURE
A6: Valuation date | F6: 46147 | S6: Active scenario: | T6: 2
A7: Current share price (NSE: ETERNAL) | B7: ₹ | F7: 251 | S7: Case name: | T7: =CHOOSE(T6,"Base Case","Optimistic Case","Pessimistic Case") -> Optimistic Case
A8: Shares outstanding | B8: cr | F8: 951.5
A9: Market capitalisation | B9: ₹ Cr | F9: =F7*F8 -> 238826.5
A10: Total debt (lease liab. + borrowings) | B10: ₹ Cr | F10: ='Balance Sheet'!F39+'Balance Sheet'!F47+'Balance Sheet'!F38+'Balance Sheet'!F46 -> 2045
A11: Cash, bank & investments | B11: ₹ Cr | F11: ='Balance Sheet'!F13+'Balance Sheet'!F20+'Balance Sheet'!F22+'Balance Sheet'!F23 -> 16806
A12: Total capital (Equity + Debt) | B12: ₹ Cr | F12: =F9+F10 -> 240871.5
A14: WACC BUILD
A15: Risk-free rate (10Y India G-Sec) | B15: % | F15: 0.07
A16: Equity Risk Premium (India) | B16: % | F16: 0.0675
A17: Beta (levered, forward-looking) | B17: x | F17: =CHOOSE($T$6,T17,U17,V17) -> 0.75 | S17: Beta — case input | T17: 0.9 | U17: 0.75 | V17: 1.1
A18: Cost of equity (CAPM) | B18: % | F18: =F15+F17*F16 -> 0.120625 | S18: Cost of equity — case | T18: =$F$15+T17*$F$16 -> 0.13075 | U18: =$F$15+U17*$F$16 -> 0.120625 | V18: =$F$15+V17*$F$16 -> 0.14425
A19: Pre-tax cost of debt | B19: % | F19: 0.09
A20: Statutory tax rate (Section 115BAA) | B20: % | F20: 0.2517
A21: After-tax cost of debt | B21: % | F21: =F19*(1-F20) -> 0.067347
A22: Weight of equity (E/V) | B22: % | F22: =F9/F12 -> 0.99151
A23: Weight of debt (D/V) | B23: % | F23: =F10/F12 -> 0.008490004
A24: WACC | B24: % | F24: =F22*F18+F23*F21 -> 0.12017267 | S24: WACC — case | T24: =$F$22*T18+$F$23*$F$21 -> 0.13021171 | U24: =$F$22*U18+$F$23*$F$21 -> 0.12017267 | V24: =$F$22*V18+$F$23*$F$21 -> 0.14359709
A26: TERMINAL ASSUMPTIONS
A27: Forecast horizon | B27: yrs | F27: 10
A28: Terminal growth rate (perpetual) | B28: % | F28: =CHOOSE($T$6,T28,U28,V28) -> 0.06 | S28: Terminal g — case input | T28: 0.05 | U28: 0.06 | V28: 0.04
A29: Terminal effective tax rate | B29: % | F29: 0.2517
A32: Food Delivery | B32: % | G32: =CHOOSE($T$6,G56,G57,G58) -> 0.3 | H32: =CHOOSE($T$6,H56,H57,H58) -> 0.27 | I32: =CHOOSE($T$6,I56,I57,I58) -> 0.24 | J32: =CHOOSE($T$6,J56,J57,J58) -> 0.22 | K32: =CHOOSE($T$6,K56,K57,K58) -> 0.2 | L32: =CHOOSE($T$6,L56,L57,L58) -> 0.18 | M32: =CHOOSE($T$6,M56,M57,M58) -> 0.16 | N32: =CHOOSE($T$6,N56,N57,N58) -> 0.14 | ... Q32: =CHOOSE($T$6,Q56,Q57,Q58) -> 0.06
A33: Hyperpure (B2B supplies) | B33: % | G33: =CHOOSE($T$6,G59,G60,G61) -> 0.75 | H33: =CHOOSE($T$6,H59,H60,H61) -> 0.6 | I33: =CHOOSE($T$6,I59,I60,I61) -> 0.48 | J33: =CHOOSE($T$6,J59,J60,J61) -> 0.4 | K33: =CHOOSE($T$6,K59,K60,K61) -> 0.35 | L33: =CHOOSE($T$6,L59,L60,L61) -> 0.3 | M33: =CHOOSE($T$6,M59,M60,M61) -> 0.25 | N33: =CHOOSE($T$6,N59,N60,N61) -> 0.22 | ... Q33: =CHOOSE($T$6,Q59,Q60,Q61) -> 0.06
A34: Quick Commerce (Blinkit) | B34: % | G34: =CHOOSE($T$6,G62,G63,G64) -> 1.2 | H34: =CHOOSE($T$6,H62,H63,H64) -> 0.9 | I34: =CHOOSE($T$6,I62,I63,I64) -> 0.65 | J34: =CHOOSE($T$6,J62,J63,J64) -> 0.5 | K34: =CHOOSE($T$6,K62,K63,K64) -> 0.4 | L34: =CHOOSE($T$6,L62,L63,L64) -> 0.35 | M34: =CHOOSE($T$6,M62,M63,M64) -> 0.28 | N34: =CHOOSE($T$6,N62,N63,N64) -> 0.22 | ... Q34: =CHOOSE($T$6,Q62,Q63,Q64) -> 0.06
A35: Going Out | B35: % | G35: =CHOOSE($T$6,G65,G66,G67) -> 1.2 | H35: =CHOOSE($T$6,H65,H66,H67) -> 0.85 | I35: =CHOOSE($T$6,I65,I66,I67) -> 0.65 | J35: =CHOOSE($T$6,J65,J66,J67) -> 0.5 | K35: =CHOOSE($T$6,K65,K66,K67) -> 0.4 | L35: =CHOOSE($T$6,L65,L66,L67) -> 0.3 | M35: =CHOOSE($T$6,M65,M66,M67) -> 0.22 | N35: =CHOOSE($T$6,N65,N66,N67) -> 0.18 | ... Q35: =CHOOSE($T$6,Q65,Q66,Q67) -> 0.06
A36: All other segments | B36: % | G36: =CHOOSE($T$6,G68,G69,G70) -> 0.15 | H36: =CHOOSE($T$6,H68,H69,H70) -> 0.15 | I36: =CHOOSE($T$6,I68,I69,I70) -> 0.15 | J36: =CHOOSE($T$6,J68,J69,J70) -> 0.12 | K36: =CHOOSE($T$6,K68,K69,K70) -> 0.1 | L36: =CHOOSE($T$6,L68,L69,L70) -> 0.08 | M36: =CHOOSE($T$6,M68,M69,M70) -> 0.08 | N36: =CHOOSE($T$6,N68,N69,N70) -> 0.08 | ... Q36: =CHOOSE($T$6,Q68,Q69,Q70) -> 0.06
A38: SEGMENT MARGIN — Segment Result % of Segment Revenue
A39: Food Delivery | B39: % | G39: =CHOOSE($T$6,G73,G74,G75) -> 0.23 | H39: =CHOOSE($T$6,H73,H74,H75) -> 0.24 | I39: =CHOOSE($T$6,I73,I74,I75) -> 0.25 | J39: =CHOOSE($T$6,J73,J74,J75) -> 0.26 | K39: =CHOOSE($T$6,K73,K74,K75) -> 0.27 | L39: =CHOOSE($T$6,L73,L74,L75) -> 0.28 | M39: =CHOOSE($T$6,M73,M74,M75) -> 0.28 | N39: =CHOOSE($T$6,N73,N74,N75) -> 0.28 | ... Q39: =CHOOSE($T$6,Q73,Q74,Q75) -> 0.28
A40: Hyperpure (B2B supplies) | B40: % | G40: =CHOOSE($T$6,G76,G77,G78) -> 0.02 | H40: =CHOOSE($T$6,H76,H77,H78) -> 0.03 | I40: =CHOOSE($T$6,I76,I77,I78) -> 0.04 | J40: =CHOOSE($T$6,J76,J77,J78) -> 0.05 | K40: =CHOOSE($T$6,K76,K77,K78) -> 0.06 | L40: =CHOOSE($T$6,L76,L77,L78) -> 0.07 | M40: =CHOOSE($T$6,M76,M77,M78) -> 0.07 | N40: =CHOOSE($T$6,N76,N77,N78) -> 0.07 | ... Q40: =CHOOSE($T$6,Q76,Q77,Q78) -> 0.07
A41: Quick Commerce (Blinkit) | B41: % | G41: =CHOOSE($T$6,G79,G80,G81) -> 0.03 | H41: =CHOOSE($T$6,H79,H80,H81) -> 0.07 | I41: =CHOOSE($T$6,I79,I80,I81) -> 0.11 | J41: =CHOOSE($T$6,J79,J80,J81) -> 0.14 | K41: =CHOOSE($T$6,K79,K80,K81) -> 0.16 | L41: =CHOOSE($T$6,L79,L80,L81) -> 0.17 | M41: =CHOOSE($T$6,M79,M80,M81) -> 0.18 | N41: =CHOOSE($T$6,N79,N80,N81) -> 0.19 | ... Q41: =CHOOSE($T$6,Q79,Q80,Q81) -> 0.19
A42: Going Out | B42: % | G42: =CHOOSE($T$6,G82,G83,G84) -> -0.03 | H42: =CHOOSE($T$6,H82,H83,H84) -> 0 | I42: =CHOOSE($T$6,I82,I83,I84) -> 0.04 | J42: =CHOOSE($T$6,J82,J83,J84) -> 0.08 | K42: =CHOOSE($T$6,K82,K83,K84) -> 0.12 | L42: =CHOOSE($T$6,L82,L83,L84) -> 0.15 | M42: =CHOOSE($T$6,M82,M83,M84) -> 0.17 | N42: =CHOOSE($T$6,N82,N83,N84) -> 0.18 | ... Q42: =CHOOSE($T$6,Q82,Q83,Q84) -> 0.19
A43: All other segments | B43: % | G43: =CHOOSE($T$6,G85,G86,G87) -> -0.2 | H43: =CHOOSE($T$6,H85,H86,H87) -> -0.1 | I43: =CHOOSE($T$6,I85,I86,I87) -> 0 | J43: =CHOOSE($T$6,J85,J86,J87) -> 0.05 | K43: =CHOOSE($T$6,K85,K86,K87) -> 0.08 | L43: =CHOOSE($T$6,L85,L86,L87) -> 0.08 | M43: =CHOOSE($T$6,M85,M86,M87) -> 0.08 | N43: =CHOOSE($T$6,N85,N86,N87) -> 0.08 | ... Q43: =CHOOSE($T$6,Q85,Q86,Q87) -> 0.08
A45: CONSOLIDATED RATIOS (% of Revenue unless stated)
A46: Share-based payment expense (SBP) | B46: % | G46: =CHOOSE($T$6,G90,G91,G92) -> 0.03 | H46: =CHOOSE($T$6,H90,H91,H92) -> 0.025 | I46: =CHOOSE($T$6,I90,I91,I92) -> 0.022 | J46: =CHOOSE($T$6,J90,J91,J92) -> 0.02 | K46: =CHOOSE($T$6,K90,K91,K92) -> 0.018 | L46: =CHOOSE($T$6,L90,L91,L92) -> 0.015 | M46: =CHOOSE($T$6,M90,M91,M92) -> 0.015 | N46: =CHOOSE($T$6,N90,N91,N92) -> 0.015 | ... Q46: =CHOOSE($T$6,Q90,Q91,Q92) -> 0.013
A47: Depreciation & amortisation (D&A) | B47: % | G47: =CHOOSE($T$6,G93,G94,G95) -> 0.04 | H47: =CHOOSE($T$6,H93,H94,H95) -> 0.038 | I47: =CHOOSE($T$6,I93,I94,I95) -> 0.036 | J47: =CHOOSE($T$6,J93,J94,J95) -> 0.035 | K47: =CHOOSE($T$6,K93,K94,K95) -> 0.034 | L47: =CHOOSE($T$6,L93,L94,L95) -> 0.033 | M47: =CHOOSE($T$6,M93,M94,M95) -> 0.033 | N47: =CHOOSE($T$6,N93,N94,N95) -> 0.033 | ... Q47: =CHOOSE($T$6,Q93,Q94,Q95) -> 0.033
...

Sheet Scenarios
A1: Eternal Limited (formerly Zomato Limited) — Scenario DCF Engines
A2: Three parallel FCFF DCFs running off Base / Optimistic / Pessimistic driver inputs from the Assumptions sheet. All values in INR crores unless stated.
A3: Active case: | B3: =Assumptions!T7 -> Optimistic Case | D3: (Toggle scenarios in Assumptions!T6 — 1=Base, 2=Opt, 3=Pess. Each block below is computed independently from its case inputs.)
A5: Particulars | B5: Unit | C5: FY25A | D5: FY26E | E5: FY27E | F5: FY28E | G5: FY29E | H5: FY30E | I5: FY31E | J5: FY32E | K5: FY33E | L5: FY34E | M5: FY35E | N5: Terminal
A6: BASE CASE
A8: SEGMENT REVENUE
A9: Food Delivery | B9: ₹ Cr | C9: =DCF!F7 -> 8080 | D9: =C9*(1+Assumptions!G56) -> 10100 | E9: =D9*(1+Assumptions!H56) -> 12322 | F9: =E9*(1+Assumptions!I56) -> 14663.18 | G9: =F9*(1+Assumptions!J56) -> 17155.921 | H9: =G9*(1+Assumptions!K56) -> 19729.309 | I9: =H9*(1+Assumptions!L56) -> 22294.119 | J9: =I9*(1+Assumptions!M56) -> 24969.413 | K9: =J9*(1+Assumptions!N56) -> 27716.049 | ... N9: =M9*(1+Assumptions!Q56) -> 34893.119
A10: Hyperpure (B2B supplies) | B10: ₹ Cr | C10: =DCF!F8 -> 6196 | D10: =C10*(1+Assumptions!G59) -> 10223.4 | E10: =D10*(1+Assumptions!H59) -> 15335.1 | F10: =E10*(1+Assumptions!I59) -> 21162.438 | G10: =F10*(1+Assumptions!J59) -> 27511.169 | H10: =G10*(1+Assumptions!K59) -> 34388.962 | I10: =H10*(1+Assumptions!L59) -> 41954.533 | J10: =I10*(1+Assumptions!M59) -> 49506.349 | K10: =J10*(1+Assumptions!N59) -> 56932.302 | ... N10: =M10*(1+Assumptions!Q59) -> 73647.626
A11: Quick Commerce (Blinkit) | B11: ₹ Cr | C11: =DCF!F9 -> 5206 | D11: =C11*(1+Assumptions!G62) -> 10412 | E11: =D11*(1+Assumptions!H62) -> 18221 | F11: =E11*(1+Assumptions!I62) -> 28242.55 | G11: =F11*(1+Assumptions!J62) -> 39539.57 | H11: =G11*(1+Assumptions!K62) -> 51401.441 | I11: =H11*(1+Assumptions!L62) -> 64251.801 | J11: =I11*(1+Assumptions!M62) -> 77102.161 | K11: =J11*(1+Assumptions!N62) -> 89438.507 | ... N11: =M11*(1+Assumptions!Q62) -> 116730.67
A12: Going Out | B12: ₹ Cr | C12: =DCF!F10 -> 737 | D12: =C12*(1+Assumptions!G65) -> 1474 | E12: =D12*(1+Assumptions!H65) -> 2505.8 | F12: =E12*(1+Assumptions!I65) -> 3758.7 | G12: =F12*(1+Assumptions!J65) -> 5074.245 | H12: =G12*(1+Assumptions!K65) -> 6342.8062 | I12: =H12*(1+Assumptions!L65) -> 7611.3675 | J12: =I12*(1+Assumptions!M65) -> 8753.0726 | K12: =J12*(1+Assumptions!N65) -> 9803.4413 | ... N12: =M12*(1+Assumptions!Q65) -> 12228.813
A13: All other segments | B13: ₹ Cr | C13: =DCF!F11 -> 24 | D13: =C13*(1+Assumptions!G68) -> 26.4 | E13: =D13*(1+Assumptions!H68) -> 29.04 | F13: =E13*(1+Assumptions!I68) -> 31.944 | G13: =F13*(1+Assumptions!J68) -> 34.49952 | H13: =G13*(1+Assumptions!K68) -> 37.259482 | I13: =H13*(1+Assumptions!L68) -> 39.122456 | J13: =I13*(1+Assumptions!M68) -> 41.078578 | K13: =J13*(1+Assumptions!N68) -> 43.132507 | ... N13: =M13*(1+Assumptions!Q68) -> 49.931269
A14: Total Revenue from Operations | B14: ₹ Cr | C14: =SUM(C9:C13) -> 20243 | D14: =SUM(D9:D13) -> 32235.8 | E14: =SUM(E9:E13) -> 48412.94 | F14: =SUM(F9:F13) -> 67858.812 | G14: =SUM(G9:G13) -> 89315.405 | H14: =SUM(H9:H13) -> 111899.78 | I14: =SUM(I9:I13) -> 136150.94 | J14: =SUM(J9:J13) -> 160372.08 | ... N14: =SUM(N9:N13) -> 237550.16
A15: YoY revenue growth | B15: % | D15: =D14/C14-1 -> 0.59244183 | E15: =E14/D14-1 -> 0.50183771 | F15: =F14/E14-1 -> 0.40166683 | G15: =G14/F14-1 -> 0.31619464 | H15: =H14/G14-1 -> 0.25286089 | I15: =I14/H14-1 -> 0.2167222 | J15: =J14/I14-1 -> 0.17789911 | K15: =K14/J14-1 -> 0.14691683 | ... N15: =N14/M14-1 -> 0.05
A17: SEGMENT RESULTS (≈ Adj. EBITDA)
A18: Food Delivery | B18: ₹ Cr | D18: =D9*Assumptions!G73 -> 2121 | E18: =E9*Assumptions!H73 -> 2710.84 | F18: =F9*Assumptions!I73 -> 3372.5314 | G18: =G9*Assumptions!J73 -> 4117.4209 | H18: =H9*Assumptions!K73 -> 4735.0341 | I18: =I9*Assumptions!L73 -> 5573.5297 | J18: =J9*Assumptions!M73 -> 6242.3533 | K18: =K9*Assumptions!N73 -> 6929.0121 | ... N18: =N9*Assumptions!Q73 -> 8723.2798
A19: Hyperpure (B2B supplies) | B19: ₹ Cr | D19: =D10*Assumptions!G76 -> 102.234 | E19: =E10*Assumptions!H76 -> 306.702 | F19: =F10*Assumptions!I76 -> 634.87314 | G19: =G10*Assumptions!J76 -> 1100.4468 | H19: =H10*Assumptions!K76 -> 1719.4481 | I19: =I10*Assumptions!L76 -> 2097.7267 | J19: =J10*Assumptions!M76 -> 2475.3175 | K19: =K10*Assumptions!N76 -> 2846.6151 | ... N19: =N10*Assumptions!Q76 -> 3682.3813
A20: Quick Commerce (Blinkit) | B20: ₹ Cr | D20: =D11*Assumptions!G79 -> 208.24 | E20: =E11*Assumptions!H79 -> 911.05 | F20: =F11*Assumptions!I79 -> 2259.404 | G20: =G11*Assumptions!J79 -> 3953.957 | H20: =H11*Assumptions!K79 -> 6168.1729 | I20: =I11*Assumptions!L79 -> 8352.7342 | J20: =J11*Assumptions!M79 -> 10794.303 | K20: =K11*Assumptions!N79 -> 13415.776 | ... N20: =N11*Assumptions!Q79 -> 17509.6
A21: Going Out | B21: ₹ Cr | D21: =D12*Assumptions!G82 -> -73.7 | E21: =E12*Assumptions!H82 -> -50.116 | F21: =F12*Assumptions!I82 -> 75.174 | G21: =G12*Assumptions!J82 -> 253.71225 | H21: =H12*Assumptions!K82 -> 507.4245 | I21: =I12*Assumptions!L82 -> 761.13675 | J21: =J12*Assumptions!M82 -> 1050.3687 | K21: =K12*Assumptions!N82 -> 1372.4818 | ... N21: =N12*Assumptions!Q82 -> 1834.3219
A22: All other segments | B22: ₹ Cr | D22: =D13*Assumptions!G85 -> -7.92 | E22: =E13*Assumptions!H85 -> -5.808 | F22: =F13*Assumptions!I85 -> -3.1944 | G22: =G13*Assumptions!J85 -> 0 | H22: =H13*Assumptions!K85 -> 1.8629741 | I22: =I13*Assumptions!L85 -> 1.9561228 | J22: =J13*Assumptions!M85 -> 2.0539289 | K22: =K13*Assumptions!N85 -> 2.1566254 | ... N22: =N13*Assumptions!Q85 -> 2.4965634
A23: Total Adj. EBITDA | B23: ₹ Cr | D23: =SUM(D18:D22) -> 2349.854 | E23: =SUM(E18:E22) -> 3872.668 | F23: =SUM(F18:F22) -> 6338.7881 | G23: =SUM(G18:G22) -> 9425.537 | H23: =SUM(H18:H22) -> 13131.943 | I23: =SUM(I18:I22) -> 16787.083 | J23: =SUM(J18:J22) -> 20564.396 | K23: =SUM(K18:K22) -> 24566.042 | ... N23: =SUM(N18:N22) -> 31752.08
A24: Adj. EBITDA margin | B24: % | D24: =D23/D14 -> 0.072895787 | E24: =E23/E14 -> 0.079992415 | F24: =F23/F14 -> 0.093411422 | G24: =G23/G14 -> 0.10553092 | H24: =H23/H14 -> 0.1173545 | I24: =I23/I14 -> 0.12329759 | J24: =J23/J14 -> 0.12822928 | K24: =K23/K14 -> 0.13355942 | ... N24: =N23/N14 -> 0.13366474
A26: Less: Share-based payment expense | B26: ₹ Cr | D26: =-D14*Assumptions!G90 -> -1128.253 | E26: =-E14*Assumptions!H90 -> -1452.3882 | F26: =-F14*Assumptions!I90 -> -1832.1879 | G26: =-G14*Assumptions!J90 -> -2232.8851 | H26: =-H14*Assumptions!K90 -> -2461.7951 | I26: =-I14*Assumptions!L90 -> -2723.0189 | J26: =-J14*Assumptions!M90 -> -2886.6974 | K26: =-K14*Assumptions!N90 -> -3126.8683 | ... N26: =-N14*Assumptions!Q90 -> -3563.2523
A27: Reported EBITDA | B27: ₹ Cr | D27: =D23+D26 -> 1221.601 | E27: =E23+E26 -> 2420.2798 | F27: =F23+F26 -> 4506.6002 | G27: =G23+G26 -> 7192.6519 | H27: =H23+H26 -> 10670.147 | I27: =I23+I26 -> 14064.065 | J27: =J23+J26 -> 17677.699 | K27: =K23+K26 -> 21439.173 | ... N27: =N23+N26 -> 28188.827
A28: Less: Depreciation & amortisation | B28: ₹ Cr | D28: =-D14*Assumptions!G93 -> -1386.1394 | E28: =-E14*Assumptions!H93 -> -2033.3435 | F28: =-F14*Assumptions!I93 -> -2714.3525 | G28: =-G14*Assumptions!J93 -> -3393.9854 | H28: =-H14*Assumptions!K93 -> -4140.2918 | I28: =-I14*Assumptions!L93 -> -4901.434 | J28: =-J14*Assumptions!M93 -> -5613.0226 | K28: =-K14*Assumptions!N93 -> -6437.6701 | ... N28: =-N14*Assumptions!Q93 -> -8314.2555
A29: EBIT | B29: ₹ Cr | D29: =D27+D28 -> -164.5384 | E29: =E27+E28 -> 386.93632 | F29: =F27+F28 -> 1792.2477 | G29: =G27+G28 -> 3798.6665 | H29: =H27+H28 -> 6529.8557 | I29: =I27+I28 -> 9162.6306 | J29: =J27+J28 -> 12064.676 | K29: =K27+K28 -> 15001.503 | ... N29: =N27+N28 -> 19874.572
A30: EBIT margin | B30: % | D30: =D29/D14 -> -0.0051042133 | E30: =E29/E14 -> 0.0079924153 | F30: =F29/F14 -> 0.026411422 | G30: =G29/G14 -> 0.042530922 | H30: =H29/H14 -> 0.058354501 | I30: =I29/I14 -> 0.067297592 | J30: =J29/J14 -> 0.075229282 | K30: =K29/K14 -> 0.081559416 | ... N30: =N29/N14 -> 0.083664739
A31: Less: Cash tax on EBIT | B31: ₹ Cr | D31: =-MAX(D29,0)*Assumptions!G102 -> 0 | E31: =-MAX(E29,0)*Assumptions!H102 -> 0 | F31: =-MAX(F29,0)*Assumptions!I102 -> -179.22477 | G31: =-MAX(G29,0)*Assumptions!J102 -> -683.75997 | H31: =-MAX(H29,0)*Assumptions!K102 -> -1436.5683 | I31: =-MAX(I29,0)*Assumptions!L102 -> -2308.9829 | J31: =-MAX(J29,0)*Assumptions!M102 -> -3040.2984 | K31: =-MAX(K29,0)*Assumptions!N102 -> -3780.3788 | ... N31: =-MAX(N29,0)*Assumptions!Q102 -> -5008.3921
A32: NOPAT | B32: ₹ Cr | D32: =D29+D31 -> -164.5384 | E32: =E29+E31 -> 386.93632 | F32: =F29+F31 -> 1613.023 | G32: =G29+G31 -> 3114.9065 | H32: =H29+H31 -> 5093.2875 | I32: =I29+I31 -> 6853.6477 | J32: =J29+J31 -> 9024.3777 | K32: =K29+K31 -> 11221.124 | ... N32: =N29+N31 -> 14866.18
A33: Plus: D&A (add-back) | B33: ₹ Cr | D33: =-D28 -> 1386.1394 | E33: =-E28 -> 2033.3435 | F33: =-F28 -> 2714.3525 | G33: =-G28 -> 3393.9854 | H33: =-H28 -> 4140.2918 | I33: =-I28 -> 4901.434 | J33: =-J28 -> 5613.0226 | K33: =-K28 -> 6437.6701 | ... N33: =-N28 -> 8314.2555
A34: Less: Capital expenditure | B34: ₹ Cr | D34: =-D14*Assumptions!G96 -> -1772.969 | E34: =-E14*Assumptions!H96 -> -2420.647 | F34: =-F14*Assumptions!I96 -> -3053.6465 | G34: =-G14*Assumptions!J96 -> -3572.6162 | H34: =-H14*Assumptions!K96 -> -4252.1915 | I34: =-I14*Assumptions!L96 -> -4765.283 | J34: =-J14*Assumptions!M96 -> -5613.0226 | K34: =-K14*Assumptions!N96 -> -6437.6701 | ... N34: =-N14*Assumptions!Q96 -> -8314.2555
A35: Less: Change in NWC | B35: ₹ Cr | D35: =-(D14-C14)*Assumptions!G99 -> -959.424 | E35: =-(E14-D14)*Assumptions!H99 -> -1294.1712 | F35: =-(F14-E14)*Assumptions!I99 -> -1361.211 | G35: =-(G14-F14)*Assumptions!J99 -> -1501.9615 | H35: =-(H14-G14)*Assumptions!K99 -> -1355.0624 | I35: =-(I14-H14)*Assumptions!L99 -> -1455.07 | J35: =-(J14-I14)*Assumptions!M99 -> -1211.0566 | K35: =-(K14-J14)*Assumptions!N99 -> -1178.0678 | ... N35: =-(N14-M14)*Assumptions!Q99 -> -565.59561
A36: Free Cash Flow to Firm (FCFF) | B36: ₹ Cr | D36: =D32+D33+D34+D35 -> -1510.792 | E36: =E32+E33+E34+E35 -> -1294.5384 | F36: =F32+F33+F34+F35 -> -87.482138 | G36: =G32+G33+G34+G35 -> 1434.3142 | H36: =H32+H33+H34+H35 -> 3626.3253 | I36: =I32+I33+I34+I35 -> 5534.7286 | J36: =J32+J33+J34+J35 -> 7813.3211 | K36: =K32+K33+K34+K35 -> 10043.057 | ... N36: =N32+N33+N34+N35 -> 14300.584
A37: FCFF margin | B37: % | D37: =D36/D14 -> -0.0468669 | E37: =E36/E14 -> -0.026739512 | F37: =F36/F14 -> -0.0012891787 | G37: =G36/G14 -> 0.016058979 | H37: =H36/H14 -> 0.032406904 | I37: =I36/I14 -> 0.040651416 | J37: =J36/J14 -> 0.04871996 | K37: =K36/K14 -> 0.054601584 | ... N37: =N36/N14 -> 0.060200273
A39: Forecast year (t) | B39: # | D39: 1 | E39: =D39+1 -> 2 | F39: =E39+1 -> 3 | G39: =F39+1 -> 4 | H39: =G39+1 -> 5 | I39: =H39+1 -> 6 | J39: =I39+1 -> 7 | K39: =J39+1 -> 8 | L39: =K39+1 -> 9 | M39: =L39+1 -> 10
A40: Discount factor | B40: x | D40: =1/(1+Assumptions!$T$24)^D39 -> 0.88478998 | E40: =1/(1+Assumptions!$T$24)^E39 -> 0.78285332 | F40: =1/(1+Assumptions!$T$24)^F39 -> 0.69266077 | G40: =1/(1+Assumptions!$T$24)^G39 -> 0.61285932 | H40: =1/(1+Assumptions!$T$24)^H39 -> 0.54225178 | I40: =1/(1+Assumptions!$T$24)^I39 -> 0.47977895 | J40: =1/(1+Assumptions!$T$24)^J39 -> 0.42450361 | K40: =1/(1+Assumptions!$T$24)^K39 -> 0.37559654 | ... M40: =1/(1+Assumptions!$T$24)^M39 -> 0.294037
A41: PV of FCFF | B41: ₹ Cr | D41: =D36*D40 -> -1336.7336 | E41: =E36*E40 -> -1013.4337 | F41: =F36*F40 -> -60.595445 | G41: =G36*G40 -> 879.03284 | H41: =H36*H40 -> 1966.3814 | I41: =I36*I40 -> 2655.4463 | J41: =J36*J40 -> 3316.783 | K41: =K36*K40 -> 3772.1373 | ... M41: =M36*M40 -> 3867.6672
A43: Sum of PV of explicit FCFF (FY26E–FY35E) | B43: ₹ Cr | D43: =SUM(D41:M41) -> 17973.636
A44: Terminal year FCFF (FY35E × (1+g)) | B44: ₹ Cr | D44: =M36*(1+Assumptions!$T$28) -> 13811.359
A45: Terminal Value (Gordon growth) | B45: ₹ Cr | D45: =D44/(Assumptions!$T$24-Assumptions!$T$28) -> 172186.32
A46: PV of Terminal Value | B46: ₹ Cr | D46: =D45/(1+Assumptions!$T$24)^Assumptions!$F$27 -> 50629.149
...

Sheet DCF
A1: Eternal Limited — DCF Valuation Model
A2: FCFF approach. Forecast FY26E–FY35E + Gordon growth terminal value. All values in INR crores.
A3: Active case: | B3: =Assumptions!T7 -> Optimistic Case | D3: WACC | E3: =Assumptions!F24 -> 0.12017267 | F3: Term g | G3: =Assumptions!F28 -> 0.06 | H3: Implied / share | I3: =F54 -> 287.17054 | J3: Upside | K3: =F56 -> 0.14410573
A5: Particulars | B5: Unit | C5: FY22A | D5: FY23A | E5: FY24A | F5: FY25A | G5: FY26E | H5: FY27E | I5: FY28E | J5: FY29E | K5: FY30E | L5: FY31E | M5: FY32E | N5: FY33E | O5: FY34E | P5: FY35E | Q5: Terminal
A6: SEGMENT REVENUE
A7: Food Delivery | B7: ₹ Cr | E7: 6361 | F7: 8080 | G7: =F7*(1+Assumptions!G32) -> 10504 | H7: =G7*(1+Assumptions!H32) -> 13340.08 | I7: =H7*(1+Assumptions!I32) -> 16541.699 | J7: =I7*(1+Assumptions!J32) -> 20180.873 | K7: =J7*(1+Assumptions!K32) -> 24217.048 | L7: =K7*(1+Assumptions!L32) -> 28576.116 | M7: =L7*(1+Assumptions!M32) -> 33148.295 | N7: =M7*(1+Assumptions!N32) -> 37789.056 | ... Q7: =P7*(1+Assumptions!Q32) -> 49349.484
A8: Hyperpure (B2B supplies) | B8: ₹ Cr | E8: 3172 | F8: 6196 | G8: =F8*(1+Assumptions!G33) -> 10843 | H8: =G8*(1+Assumptions!H33) -> 17348.8 | I8: =H8*(1+Assumptions!I33) -> 25676.224 | J8: =I8*(1+Assumptions!J33) -> 35946.714 | K8: =J8*(1+Assumptions!K33) -> 48528.063 | L8: =K8*(1+Assumptions!L33) -> 63086.482 | M8: =L8*(1+Assumptions!M33) -> 78858.103 | N8: =M8*(1+Assumptions!N33) -> 96206.886 | ... Q8: =P8*(1+Assumptions!Q33) -> 138385.91
A9: Quick Commerce (Blinkit) | B9: ₹ Cr | E9: 2301 | F9: 5206 | G9: =F9*(1+Assumptions!G34) -> 11453.2 | H9: =G9*(1+Assumptions!H34) -> 21761.08 | I9: =H9*(1+Assumptions!I34) -> 35905.782 | J9: =I9*(1+Assumptions!J34) -> 53858.673 | K9: =J9*(1+Assumptions!K34) -> 75402.142 | L9: =K9*(1+Assumptions!L34) -> 101792.89 | M9: =L9*(1+Assumptions!M34) -> 130294.9 | N9: =M9*(1+Assumptions!N34) -> 158959.78 | ... Q9: =P9*(1+Assumptions!Q34) -> 224674.39
A10: Going Out | B10: ₹ Cr | E10: 258 | F10: 737 | G10: =F10*(1+Assumptions!G35) -> 1621.4 | H10: =G10*(1+Assumptions!H35) -> 2999.59 | I10: =H10*(1+Assumptions!I35) -> 4949.3235 | J10: =I10*(1+Assumptions!J35) -> 7423.9853 | K10: =J10*(1+Assumptions!K35) -> 10393.579 | L10: =K10*(1+Assumptions!L35) -> 13511.653 | M10: =L10*(1+Assumptions!M35) -> 16484.217 | N10: =M10*(1+Assumptions!N35) -> 19451.376 | ... Q10: =P10*(1+Assumptions!Q35) -> 25855.547
A11: All other segments | B11: ₹ Cr | E11: 22 | F11: 24 | G11: =F11*(1+Assumptions!G36) -> 27.6 | H11: =G11*(1+Assumptions!H36) -> 31.74 | I11: =H11*(1+Assumptions!I36) -> 36.501 | J11: =I11*(1+Assumptions!J36) -> 40.88112 | K11: =J11*(1+Assumptions!K36) -> 44.969232 | L11: =K11*(1+Assumptions!L36) -> 48.566771 | M11: =L11*(1+Assumptions!M36) -> 52.452112 | N11: =M11*(1+Assumptions!N36) -> 56.648281 | ... Q11: =P11*(1+Assumptions!Q36) -> 70.039028
A12: Total Revenue from Operations | B12: ₹ Cr | C12: ='P&L'!C6 -> 4192.4 | D12: ='P&L'!D6 -> 7079.4 | E12: ='P&L'!E6 -> 12114 | F12: ='P&L'!F6 -> 20243 | G12: =SUM(G7:G11) -> 34449.2 | H12: =SUM(H7:H11) -> 55481.29 | I12: =SUM(I7:I11) -> 83109.53 | J12: =SUM(J7:J11) -> 117451.13 | K12: =SUM(K7:K11) -> 158585.8 | L12: =SUM(L7:L11) -> 207015.71 | M12: =SUM(M7:M11) -> 258837.97 | N12: =SUM(N7:N11) -> 312463.75 | ... Q12: =SUM(Q7:Q11) -> 438335.37
A13: YoY revenue growth | B13: % | D13: =D12/C12-1 -> 0.68862704 | E13: =E12/D12-1 -> 0.71116196 | F13: =F12/E12-1 -> 0.67104177 | G13: =G12/F12-1 -> 0.70178333 | H13: =H12/G12-1 -> 0.61052477 | I13: =I12/H12-1 -> 0.497974 | J13: =J12/I12-1 -> 0.41320889 | K13: =K12/J12-1 -> 0.35022802 | ... Q13: =Q12/P12-1 -> 0.06
A15: SEGMENT RESULTS (≈ Adj. EBITDA)
A16: Food Delivery | B16: ₹ Cr | E16: 935 | F16: 1541 | G16: =G7*Assumptions!G39 -> 2415.92 | H16: =H7*Assumptions!H39 -> 3201.6192 | I16: =I7*Assumptions!I39 -> 4135.4248 | J16: =J7*Assumptions!J39 -> 5247.027 | K16: =K7*Assumptions!K39 -> 6538.6029 | L16: =L7*Assumptions!L39 -> 8001.3125 | M16: =M7*Assumptions!M39 -> 9281.5225 | N16: =N7*Assumptions!N39 -> 10580.936 | ... Q16: =Q7*Assumptions!Q39 -> 13817.856
A17: Hyperpure (B2B supplies) | B17: ₹ Cr | E17: -100 | F17: -43 | G17: =G8*Assumptions!G40 -> 216.86 | H17: =H8*Assumptions!H40 -> 520.464 | I17: =I8*Assumptions!I40 -> 1027.049 | J17: =J8*Assumptions!J40 -> 1797.3357 | K17: =K8*Assumptions!K40 -> 2911.6838 | L17: =L8*Assumptions!L40 -> 4416.0538 | M17: =M8*Assumptions!M40 -> 5520.0672 | N17: =N8*Assumptions!N40 -> 6734.482 | ... Q17: =Q8*Assumptions!Q40 -> 9687.0136
A18: Quick Commerce (Blinkit) | B18: ₹ Cr | E18: -253 | F18: -21 | G18: =G9*Assumptions!G41 -> 343.596 | H18: =H9*Assumptions!H41 -> 1523.2756 | I18: =I9*Assumptions!I41 -> 3949.636 | J18: =J9*Assumptions!J41 -> 7540.2142 | K18: =K9*Assumptions!K41 -> 12064.343 | L18: =L9*Assumptions!L41 -> 17304.792 | M18: =M9*Assumptions!M41 -> 23453.082 | N18: =N9*Assumptions!N41 -> 30202.358 | ... Q18: =Q9*Assumptions!Q41 -> 42688.134
A19: Going Out | B19: ₹ Cr | E19: -2 | F19: -30 | G19: =G10*Assumptions!G42 -> -48.642 | H19: =H10*Assumptions!H42 -> 0 | I19: =I10*Assumptions!I42 -> 197.97294 | J19: =J10*Assumptions!J42 -> 593.91882 | K19: =K10*Assumptions!K42 -> 1247.2295 | L19: =L10*Assumptions!L42 -> 2026.748 | M19: =M10*Assumptions!M42 -> 2802.3169 | N19: =N10*Assumptions!N42 -> 3501.2477 | ... Q19: =Q10*Assumptions!Q42 -> 4912.5539
A20: All other segments | B20: ₹ Cr | E20: -23 | F20: -12 | G20: =G11*Assumptions!G43 -> -5.52 | H20: =H11*Assumptions!H43 -> -3.174 | I20: =I11*Assumptions!I43 -> 0 | J20: =J11*Assumptions!J43 -> 2.044056 | K20: =K11*Assumptions!K43 -> 3.5975386 | L20: =L11*Assumptions!L43 -> 3.8853416 | M20: =M11*Assumptions!M43 -> 4.196169 | N20: =N11*Assumptions!N43 -> 4.5318625 | ... Q20: =Q11*Assumptions!Q43 -> 5.6031223
A21: Total Adj. EBITDA | B21: ₹ Cr | E21: =SUM(E16:E20) -> 557 | F21: =SUM(F16:F20) -> 1435 | G21: =SUM(G16:G20) -> 2922.214 | H21: =SUM(H16:H20) -> 5242.1848 | I21: =SUM(I16:I20) -> 9310.0827 | J21: =SUM(J16:J20) -> 15180.54 | K21: =SUM(K16:K20) -> 22765.456 | L21: =SUM(L16:L20) -> 31752.791 | ... Q21: =SUM(Q16:Q20) -> 71111.16
A22: Adj. EBITDA margin | B22: % | E22: =E21/E12 -> 0.045979858 | F22: =F21/F12 -> 0.070888702 | G22: =G21/G12 -> 0.084826759 | H22: =H21/H12 -> 0.094485633 | I22: =I21/I12 -> 0.11202184 | J22: =J21/J12 -> 0.12924984 | K22: =K21/K12 -> 0.14355293 | L22: =L21/L12 -> 0.15338349 | ... Q22: =Q21/Q12 -> 0.16223003
A25: Total Adj. EBITDA (segment results) | B25: ₹ Cr | E25: =E21 -> 557 | F25: =F21 -> 1435 | G25: =G21 -> 2922.214 | H25: =H21 -> 5242.1848 | I25: =I21 -> 9310.0827 | J25: =J21 -> 15180.54 | K25: =K21 -> 22765.456 | L25: =L21 -> 31752.791 | ... Q25: =Q21 -> 71111.16
A26: Less: Share-based payment expense | B26: ₹ Cr | E26: =-Equity!E29 -> 515 | F26: =-Equity!F29 -> -798 | G26: =-G12*Assumptions!G46 -> -1033.476 | H26: =-H12*Assumptions!H46 -> -1387.0323 | I26: =-I12*Assumptions!I46 -> -1828.4097 | J26: =-J12*Assumptions!J46 -> -2349.0225 | K26: =-K12*Assumptions!K46 -> -2854.5444 | L26: =-L12*Assumptions!L46 -> -3105.2357 | M26: =-M12*Assumptions!M46 -> -3882.5695 | N26: =-N12*Assumptions!N46 -> -4686.9562 | ... Q26: =-Q12*Assumptions!Q46 -> -5698.3598
A27: Reported EBITDA | B27: ₹ Cr | E27: =E25+E26 -> 1072 | F27: =F25+F26 -> 637 | G27: =G25+G26 -> 1888.738 | H27: =H25+H26 -> 3855.1525 | I27: =I25+I26 -> 7481.6731 | J27: =J25+J26 -> 12831.517 | K27: =K25+K26 -> 19910.912 | L27: =L25+L26 -> 28647.556 | ... Q27: =Q25+Q26 -> 65412.8
A28: Less: Depreciation & amortisation | B28: ₹ Cr | C28: =-'P&L'!C14 -> -150.3 | D28: =-'P&L'!D14 -> -436.9 | E28: =-'P&L'!E14 -> -526 | F28: =-'P&L'!F14 -> -863 | G28: =-G12*Assumptions!G47 -> -1377.968 | H28: =-H12*Assumptions!H47 -> -2108.289 | I28: =-I12*Assumptions!I47 -> -2991.9431 | J28: =-J12*Assumptions!J47 -> -4110.7894 | K28: =-K12*Assumptions!K47 -> -5391.9173 | L28: =-L12*Assumptions!L47 -> -6831.5184 | M28: =-M12*Assumptions!M47 -> -8541.653 | N28: =-N12*Assumptions!N47 -> -10311.304 | ... Q28: =-Q12*Assumptions!Q47 -> -14465.067
A29: EBIT | B29: ₹ Cr | E29: =E27+E28 -> 546 | F29: =F27+F28 -> -226 | G29: =G27+G28 -> 510.77 | H29: =H27+H28 -> 1746.8635 | I29: =I27+I28 -> 4489.73 | J29: =J27+J28 -> 8720.7278 | K29: =K27+K28 -> 14518.995 | L29: =L27+L28 -> 21816.037 | ... Q29: =Q27+Q28 -> 50947.733
A30: EBIT margin | B30: % | E30: =E29/E12 -> 0.045071818 | F30: =F29/F12 -> -0.011164353 | G30: =G29/G12 -> 0.014826759 | H30: =H29/H12 -> 0.031485633 | I30: =I29/I12 -> 0.054021843 | J30: =J29/J12 -> 0.074249844 | K30: =K29/K12 -> 0.09155293 | L30: =L29/L12 -> 0.10538349 | ... Q30: =Q29/Q12 -> 0.11623003
A31: Less: Cash tax on EBIT | B31: ₹ Cr | G31: =-MAX(G29,0)*Assumptions!G50 -> 0 | H31: =-MAX(H29,0)*Assumptions!H50 -> 0 | I31: =-MAX(I29,0)*Assumptions!I50 -> -359.1784 | J31: =-MAX(J29,0)*Assumptions!J50 -> -1308.1092 | K31: =-MAX(K29,0)*Assumptions!K50 -> -2903.799 | L31: =-MAX(L29,0)*Assumptions!L50 -> -5497.6414 | M31: =-MAX(M29,0)*Assumptions!M50 -> -7216.5146 | N31: =-MAX(N29,0)*Assumptions!N50 -> -9078.3745 | ... Q31: =-MAX(Q29,0)*Assumptions!Q50 -> -12838.829
A32: NOPAT | B32: ₹ Cr | G32: =G29+G31 -> 510.77 | H32: =H29+H31 -> 1746.8635 | I32: =I29+I31 -> 4130.5516 | J32: =J29+J31 -> 7412.6187 | K32: =K29+K31 -> 11615.196 | L32: =L29+L31 -> 16318.396 | M32: =M29+M31 -> 21420.448 | N32: =N29+N31 -> 26946.921 | ... Q32: =Q29+Q31 -> 38108.904
A33: Plus: D&A (add-back) | B33: ₹ Cr | G33: =-G28 -> 1377.968 | H33: =-H28 -> 2108.289 | I33: =-I28 -> 2991.9431 | J33: =-J28 -> 4110.7894 | K33: =-K28 -> 5391.9173 | L33: =-L28 -> 6831.5184 | M33: =-M28 -> 8541.653 | N33: =-N28 -> 10311.304 | ... Q33: =-Q28 -> 14465.067
A34: Less: Capital expenditure | B34: ₹ Cr | G34: =-G12*Assumptions!G48 -> -1722.46 | H34: =-H12*Assumptions!H48 -> -2496.6581 | I34: =-I12*Assumptions!I48 -> -3324.3812 | J34: =-J12*Assumptions!J48 -> -4110.7894 | K34: =-K12*Assumptions!K48 -> -5233.3315 | L34: =-L12*Assumptions!L48 -> -6210.4713 | M34: =-M12*Assumptions!M48 -> -7765.1391 | N34: =-N12*Assumptions!N48 -> -9373.9124 | ... Q34: =-Q12*Assumptions!Q48 -> -13150.061
A35: Less: Change in NWC | B35: ₹ Cr | G35: =-(G12-F12)*Assumptions!G49 -> -994.434 | H35: =-(H12-G12)*Assumptions!H49 -> -1472.2463 | I35: =-(I12-H12)*Assumptions!I49 -> -1657.6944 | J35: =-(J12-I12)*Assumptions!J49 -> -2060.4958 | K35: =-(K12-J12)*Assumptions!K49 -> -2056.7338 | L35: =-(L12-K12)*Assumptions!L49 -> -2421.4954 | M35: =-(M12-L12)*Assumptions!M49 -> -2591.1129 | N35: =-(N12-M12)*Assumptions!N49 -> -2145.0311 | ... Q35: =-(Q12-P12)*Assumptions!Q49 -> -992.45744
A36: Free Cash Flow to Firm (FCFF) | B36: ₹ Cr | G36: =G32+G33+G34+G35 -> -828.156 | H36: =H32+H33+H34+H35 -> -113.7518 | I36: =I32+I33+I34+I35 -> 2140.4191 | J36: =J32+J33+J34+J35 -> 5352.1229 | K36: =K32+K33+K34+K35 -> 9717.0478 | L36: =L32+L33+L34+L35 -> 14517.947 | M36: =M32+M33+M34+M35 -> 19605.849 | N36: =N32+N33+N34+N35 -> 25739.281 | ... Q36: =Q32+Q33+Q34+Q35 -> 38431.453
A37: FCFF margin | B37: % | G37: =G36/G12 -> -0.02403992 | H37: =H36/H12 -> -0.0020502732 | I37: =I36/I12 -> 0.025754196 | J37: =J36/J12 -> 0.045568936 | K37: =K36/K12 -> 0.061273126 | L37: =L36/L12 -> 0.070129689 | M37: =M36/M12 -> 0.075745646 | N37: =N36/N12 -> 0.082375257 | ... Q37: =Q36/Q12 -> 0.087675912
A39: PRESENT VALUE OF FCFF
A40: Forecast year (t) | B40: # | G40: 1 | H40: 2 | I40: 3 | J40: 4 | K40: 5 | L40: 6 | M40: 7 | N40: 8 | O40: 9 | P40: 10
A41: Discount factor | B41: x | G41: =1/(1+Assumptions!$F$24)^G40 -> 0.89271951 | H41: =1/(1+Assumptions!$F$24)^H40 -> 0.79694813 | I41: =1/(1+Assumptions!$F$24)^I40 -> 0.71145115 | J41: =1/(1+Assumptions!$F$24)^J40 -> 0.63512632 | K41: =1/(1+Assumptions!$F$24)^K40 -> 0.56698966 | L41: =1/(1+Assumptions!$F$24)^L40 -> 0.50616273 | M41: =1/(1+Assumptions!$F$24)^M40 -> 0.45186135 | N41: =1/(1+Assumptions!$F$24)^N40 -> 0.40338544 | ... P41: =1/(1+Assumptions!$F$24)^P40 -> 0.32147727
A42: PV of FCFF | B42: ₹ Cr | G42: =G36*G41 -> -739.31102 | H42: =H36*H41 -> -90.654284 | I42: =I36*I41 -> 1522.8036 | J42: =J36*J41 -> 3399.2741 | K42: =K36*K41 -> 5509.4656 | L42: =L36*L41 -> 7348.444 | M42: =M36*M41 -> 8859.1254 | N42: =N36*N41 -> 10382.851 | ... P42: =P36*P41 -> 11340.965
A44: TERMINAL VALUE & EQUITY BRIDGE
A45: Sum of PV of explicit FCFF (FY26E–FY35E) | B45: ₹ Cr | F45: =SUM(G42:P42) -> 58699.654
A46: Terminal year FCFF (FY35E × (1+g)) | B46: ₹ Cr | F46: =P36*(1+Assumptions!F28) -> 37394.317
...

Sheet Sensitivity
A1: Eternal Limited — DCF Sensitivity Analysis
A2: Two-way sensitivity tables for implied per share value (₹).
A3: Active case: | B3: =Assumptions!T7 -> Optimistic Case | D3: WACC: | E3: =Assumptions!F24 -> 0.12017267 | F3: Term g: | G3: =Assumptions!F28 -> 0.06 | H3: Implied / share: | I3: =DCF!F54 -> 287.17054
A5: ="Active case → "&Assumptions!T7&": WACC "&TEXT(Assumptions!F24,"0.00%")&", terminal g "&TEXT(Assumptions!F28,"0.00%")&" → ₹"&TEXT(DCF!F54,"0.00")&" / share (vs current ₹"&TEXT(DCF!F55,"0.00")&", upside "&TEXT(DCF!F56,"0.0%;(0.0%)")&")" -> Active case → Optimistic Case: WACC 12.02%, terminal g 6.00% → ₹287.17 / share (vs current ₹251.00, upside 14.4%)
A7: SENSITIVITY 1: Implied Per Share Value (₹) — WACC × Terminal Growth
A8: Terminal growth ↓ / WACC → | C8: 0.11 | D8: 0.115 | E8: 0.12 | F8: 0.13 | G8: 0.14 | H8: 0.15
B9: 0.03 | C9: {=(SUMPRODUCT(DCF!$G$36:$P$36/(1+C$8)^DCF!$G$40:$P$40)+DCF!$P$36*(1+$B9)/(C$8-$B9)/(1+C$8)^Assumptions!$F$27-Assumptions!$F$10+Assumptions!$F$11)/Assumptions!$F$8} -> 249.77679 | D9: {=(SUMPRODUCT(DCF!$G$36:$P$36/(1+D$8)^DCF!$G$40:$P$40)+DCF!$P$36*(1+$B9)/(D$8-$B9)/(1+D$8)^Assumptions!$F$27-Assumptions!$F$10+Assumptions!$F$11)/Assumptions!$F$8} -> 230.69753 | E9: {=(SUMPRODUCT(DCF!$G$36:$P$36/(1+E$8)^DCF!$G$40:$P$40)+DCF!$P$36*(1+$B9)/(E$8-$B9)/(1+E$8)^Assumptions!$F$27-Assumptions!$F$10+Assumptions!$F$11)/Assumptions!$F$8} -> 213.89492 | F9: {=(SUMPRODUCT(DCF!$G$36:$P$36/(1+F$8)^DCF!$G$40:$P$40)+DCF!$P$36*(1+$B9)/(F$8-$B9)/(1+F$8)^Assumptions!$F$27-Assumptions!$F$10+Assumptions!$F$11)/Assumptions!$F$8} -> 185.73249 | G9: {=(SUMPRODUCT(DCF!$G$36:$P$36/(1+G$8)^DCF!$G$40:$P$40)+DCF!$P$36*(1+$B9)/(G$8-$B9)/(1+G$8)^Assumptions!$F$27-Assumptions!$F$10+Assumptions!$F$11)/Assumptions!$F$8} -> 163.14775 | H9: {=(SUMPRODUCT(DCF!$G$36:$P$36/(1+H$8)^DCF!$G$40:$P$40)+DCF!$P$36*(1+$B9)/(H$8-$B9)/(1+H$8)^Assumptions!$F$27-Assumptions!$F$10+Assumptions!$F$11)/Assumptions!$F$8} -> 144.71572
B10: 0.04 | C10: {=(SUMPRODUCT(DCF!$G$36:$P$36/(1+C$8)^DCF!$G$40:$P$40)+DCF!$P$36*(1+$B10)/(C$8-$B10)/(1+C$8)^Assumptions!$F$27-Assumptions!$F$10+Assumptions!$F$11)/Assumptions!$F$8} -> 275.65869 | D10: {=(SUMPRODUCT(DCF!$G$36:$P$36/(1+D$8)^DCF!$G$40:$P$40)+DCF!$P$36*(1+$B10)/(D$8-$B10)/(1+D$8)^Assumptions!$F$27-Assumptions!$F$10+Assumptions!$F$11)/Assumptions!$F$8} -> 252.53172 | E10: {=(SUMPRODUCT(DCF!$G$36:$P$36/(1+E$8)^DCF!$G$40:$P$40)+DCF!$P$36*(1+$B10)/(E$8-$B10)/(1+E$8)^Assumptions!$F$27-Assumptions!$F$10+Assumptions!$F$11)/Assumptions!$F$8} -> 232.46426 | F10: {=(SUMPRODUCT(DCF!$G$36:$P$36/(1+F$8)^DCF!$G$40:$P$40)+DCF!$P$36*(1+$B10)/(F$8-$B10)/(1+F$8)^Assumptions!$F$27-Assumptions!$F$10+Assumptions!$F$11)/Assumptions!$F$8} -> 199.4458 | G10: {=(SUMPRODUCT(DCF!$G$36:$P$36/(1+G$8)^DCF!$G$40:$P$40)+DCF!$P$36*(1+$B10)/(G$8-$B10)/(1+G$8)^Assumptions!$F$27-Assumptions!$F$10+Assumptions!$F$11)/Assumptions!$F$8} -> 173.5124 | H10: {=(SUMPRODUCT(DCF!$G$36:$P$36/(1+H$8)^DCF!$G$40:$P$40)+DCF!$P$36*(1+$B10)/(H$8-$B10)/(1+H$8)^Assumptions!$F$27-Assumptions!$F$10+Assumptions!$F$11)/Assumptions!$F$8} -> 152.70001
B11: 0.05 | C11: {=(SUMPRODUCT(DCF!$G$36:$P$36/(1+C$8)^DCF!$G$40:$P$40)+DCF!$P$36*(1+$B11)/(C$8-$B11)/(1+C$8)^Assumptions!$F$27-Assumptions!$F$10+Assumptions!$F$11)/Assumptions!$F$8} -> 310.16789 | D11: {=(SUMPRODUCT(DCF!$G$36:$P$36/(1+D$8)^DCF!$G$40:$P$40)+DCF!$P$36*(1+$B11)/(D$8-$B11)/(1+D$8)^Assumptions!$F$27-Assumptions!$F$10+Assumptions!$F$11)/Assumptions!$F$8} -> 281.08411 | E11: {=(SUMPRODUCT(DCF!$G$36:$P$36/(1+E$8)^DCF!$G$40:$P$40)+DCF!$P$36*(1+$B11)/(E$8-$B11)/(1+E$8)^Assumptions!$F$27-Assumptions!$F$10+Assumptions!$F$11)/Assumptions!$F$8} -> 256.33911 | F11: {=(SUMPRODUCT(DCF!$G$36:$P$36/(1+F$8)^DCF!$G$40:$P$40)+DCF!$P$36*(1+$B11)/(F$8-$B11)/(1+F$8)^Assumptions!$F$27-Assumptions!$F$10+Assumptions!$F$11)/Assumptions!$F$8} -> 216.58745 | G11: {=(SUMPRODUCT(DCF!$G$36:$P$36/(1+G$8)^DCF!$G$40:$P$40)+DCF!$P$36*(1+$B11)/(G$8-$B11)/(1+G$8)^Assumptions!$F$27-Assumptions!$F$10+Assumptions!$F$11)/Assumptions!$F$8} -> 186.18031 | H11: {=(SUMPRODUCT(DCF!$G$36:$P$36/(1+H$8)^DCF!$G$40:$P$40)+DCF!$P$36*(1+$B11)/(H$8-$B11)/(1+H$8)^Assumptions!$F$27-Assumptions!$F$10+Assumptions!$F$11)/Assumptions!$F$8} -> 162.28117
B12: 0.06 | C12: {=(SUMPRODUCT(DCF!$G$36:$P$36/(1+C$8)^DCF!$G$40:$P$40)+DCF!$P$36*(1+$B12)/(C$8-$B12)/(1+C$8)^Assumptions!$F$27-Assumptions!$F$10+Assumptions!$F$11)/Assumptions!$F$8} -> 358.48076 | D12: {=(SUMPRODUCT(DCF!$G$36:$P$36/(1+D$8)^DCF!$G$40:$P$40)+DCF!$P$36*(1+$B12)/(D$8-$B12)/(1+D$8)^Assumptions!$F$27-Assumptions!$F$10+Assumptions!$F$11)/Assumptions!$F$8} -> 320.01919 | E12: {=(SUMPRODUCT(DCF!$G$36:$P$36/(1+E$8)^DCF!$G$40:$P$40)+DCF!$P$36*(1+$B12)/(E$8-$B12)/(1+E$8)^Assumptions!$F$27-Assumptions!$F$10+Assumptions!$F$11)/Assumptions!$F$8} -> 288.17225 | F12: {=(SUMPRODUCT(DCF!$G$36:$P$36/(1+F$8)^DCF!$G$40:$P$40)+DCF!$P$36*(1+$B12)/(F$8-$B12)/(1+F$8)^Assumptions!$F$27-Assumptions!$F$10+Assumptions!$F$11)/Assumptions!$F$8} -> 238.6267 | G12: {=(SUMPRODUCT(DCF!$G$36:$P$36/(1+G$8)^DCF!$G$40:$P$40)+DCF!$P$36*(1+$B12)/(G$8-$B12)/(1+G$8)^Assumptions!$F$27-Assumptions!$F$10+Assumptions!$F$11)/Assumptions!$F$8} -> 202.01519 | H12: {=(SUMPRODUCT(DCF!$G$36:$P$36/(1+H$8)^DCF!$G$40:$P$40)+DCF!$P$36*(1+$B12)/(H$8-$B12)/(1+H$8)^Assumptions!$F$27-Assumptions!$F$10+Assumptions!$F$11)/Assumptions!$F$8} -> 173.99146
B13: 0.07 | C13: {=(SUMPRODUCT(DCF!$G$36:$P$36/(1+C$8)^DCF!$G$40:$P$40)+DCF!$P$36*(1+$B13)/(C$8-$B13)/(1+C$8)^Assumptions!$F$27-Assumptions!$F$10+Assumptions!$F$11)/Assumptions!$F$8} -> 430.95008 | D13: {=(SUMPRODUCT(DCF!$G$36:$P$36/(1+D$8)^DCF!$G$40:$P$40)+DCF!$P$36*(1+$B13)/(D$8-$B13)/(1+D$8)^Assumptions!$F$27-Assumptions!$F$10+Assumptions!$F$11)/Assumptions!$F$8} -> 376.25876 | E13: {=(SUMPRODUCT(DCF!$G$36:$P$36/(1+E$8)^DCF!$G$40:$P$40)+DCF!$P$36*(1+$B13)/(E$8-$B13)/(1+E$8)^Assumptions!$F$27-Assumptions!$F$10+Assumptions!$F$11)/Assumptions!$F$8} -> 332.73864 | F13: {=(SUMPRODUCT(DCF!$G$36:$P$36/(1+F$8)^DCF!$G$40:$P$40)+DCF!$P$36*(1+$B13)/(F$8-$B13)/(1+F$8)^Assumptions!$F$27-Assumptions!$F$10+Assumptions!$F$11)/Assumptions!$F$8} -> 268.01238 | G13: {=(SUMPRODUCT(DCF!$G$36:$P$36/(1+G$8)^DCF!$G$40:$P$40)+DCF!$P$36*(1+$B13)/(G$8-$B13)/(1+G$8)^Assumptions!$F$27-Assumptions!$F$10+Assumptions!$F$11)/Assumptions!$F$8} -> 222.37432 | H13: {=(SUMPRODUCT(DCF!$G$36:$P$36/(1+H$8)^DCF!$G$40:$P$40)+DCF!$P$36*(1+$B13)/(H$8-$B13)/(1+H$8)^Assumptions!$F$27-Assumptions!$F$10+Assumptions!$F$11)/Assumptions!$F$8} -> 188.62933
A15: SENSITIVITY 2: Implied Per Share Value (₹) — WACC × Terminal Adj. EBITDA Margin
A16: Terminal margin ↓ / WACC → | C16: 0.11 | D16: 0.115 | E16: 0.12 | F16: 0.13 | G16: 0.14 | H16: 0.15
B17: 0.1 | C17: {=(SUMPRODUCT(DCF!$G$36:$P$36/(1+C$16)^DCF!$G$40:$P$40)+(DCF!$P$12*(1+Assumptions!$F$28)*(($B17-Assumptions!$Q$46-Assumptions!$Q$47)*(1-Assumptions!$Q$50)+Assumptions!$Q$47-Assumptions!$Q$48)-DCF!$P$12*Assumptions!$F$28*Assumptions!$Q$49)/(C$16-Assumptions!$F$28)/(1+C$16)^Assumptions!$F$27-Assumptions!$F$10+Assumptions!$F$11)/Assumptions!$F$8} -> 215.11576 | D17: {=(SUMPRODUCT(DCF!$G$36:$P$36/(1+D$16)^DCF!$G$40:$P$40)+(DCF!$P$12*(1+Assumptions!$F$28)*(($B17-Assumptions!$Q$46-Assumptions!$Q$47)*(1-Assumptions!$Q$50)+Assumptions!$Q$47-Assumptions!$Q$48)-DCF!$P$12*Assumptions!$F$28*Assumptions!$Q$49)/(D$16-Assumptions!$F$28)/(1+D$16)^Assumptions!$F$27-Assumptions!$F$10+Assumptions!$F$11)/Assumptions!$F$8} -> 195.41531 | E17: {=(SUMPRODUCT(DCF!$G$36:$P$36/(1+E$16)^DCF!$G$40:$P$40)+(DCF!$P$12*(1+Assumptions!$F$28)*(($B17-Assumptions!$Q$46-Assumptions!$Q$47)*(1-Assumptions!$Q$50)+Assumptions!$Q$47-Assumptions!$Q$48)-DCF!$P$12*Assumptions!$F$28*Assumptions!$Q$49)/(E$16-Assumptions!$F$28)/(1+E$16)^Assumptions!$F$27-Assumptions!$F$10+Assumptions!$F$11)/Assumptions!$F$8} -> 178.94991 | F17: {=(SUMPRODUCT(DCF!$G$36:$P$36/(1+F$16)^DCF!$G$40:$P$40)+(DCF!$P$12*(1+Assumptions!$F$28)*(($B17-Assumptions!$Q$46-Assumptions!$Q$47)*(1-Assumptions!$Q$50)+Assumptions!$Q$47-Assumptions!$Q$48)-DCF!$P$12*Assumptions!$F$28*Assumptions!$Q$49)/(F$16-Assumptions!$F$28)/(1+F$16)^Assumptions!$F$27-Assumptions!$F$10+Assumptions!$F$11)/Assumptions!$F$8} -> 152.97018 | G17: {=(SUMPRODUCT(DCF!$G$36:$P$36/(1+G$16)^DCF!$G$40:$P$40)+(DCF!$P$12*(1+Assumptions!$F$28)*(($B17-Assumptions!$Q$46-Assumptions!$Q$47)*(1-Assumptions!$Q$50)+Assumptions!$Q$47-Assumptions!$Q$48)-DCF!$P$12*Assumptions!$F$28*Assumptions!$Q$49)/(G$16-Assumptions!$F$28)/(1+G$16)^Assumptions!$F$27-Assumptions!$F$10+Assumptions!$F$11)/Assumptions!$F$8} -> 133.3867 | H17: {=(SUMPRODUCT(DCF!$G$36:$P$36/(1+H$16)^DCF!$G$40:$P$40)+(DCF!$P$12*(1+Assumptions!$F$28)*(($B17-Assumptions!$Q$46-Assumptions!$Q$47)*(1-Assumptions!$Q$50)+Assumptions!$Q$47-Assumptions!$Q$48)-DCF!$P$12*Assumptions!$F$28*Assumptions!$Q$49)/(H$16-Assumptions!$F$28)/(1+H$16)^Assumptions!$F$27-Assumptions!$F$10+Assumptions!$F$11)/Assumptions!$F$8} -> 118.09015
B18: 0.12 | C18: {=(SUMPRODUCT(DCF!$G$36:$P$36/(1+C$16)^DCF!$G$40:$P$40)+(DCF!$P$12*(1+Assumptions!$F$28)*(($B18-Assumptions!$Q$46-Assumptions!$Q$47)*(1-Assumptions!$Q$50)+Assumptions!$Q$47-Assumptions!$Q$48)-DCF!$P$12*Assumptions!$F$28*Assumptions!$Q$49)/(C$16-Assumptions!$F$28)/(1+C$16)^Assumptions!$F$27-Assumptions!$F$10+Assumptions!$F$11)/Assumptions!$F$8} -> 263.65909 | D18: {=(SUMPRODUCT(DCF!$G$36:$P$36/(1+D$16)^DCF!$G$40:$P$40)+(DCF!$P$12*(1+Assumptions!$F$28)*(($B18-Assumptions!$Q$46-Assumptions!$Q$47)*(1-Assumptions!$Q$50)+Assumptions!$Q$47-Assumptions!$Q$48)-DCF!$P$12*Assumptions!$F$28*Assumptions!$Q$49)/(D$16-Assumptions!$F$28)/(1+D$16)^Assumptions!$F$27-Assumptions!$F$10+Assumptions!$F$11)/Assumptions!$F$8} -> 237.60613 | E18: {=(SUMPRODUCT(DCF!$G$36:$P$36/(1+E$16)^DCF!$G$40:$P$40)+(DCF!$P$12*(1+Assumptions!$F$28)*(($B18-Assumptions!$Q$46-Assumptions!$Q$47)*(1-Assumptions!$Q$50)+Assumptions!$Q$47-Assumptions!$Q$48)-DCF!$P$12*Assumptions!$F$28*Assumptions!$Q$49)/(E$16-Assumptions!$F$28)/(1+E$16)^Assumptions!$F$27-Assumptions!$F$10+Assumptions!$F$11)/Assumptions!$F$8} -> 215.93255 | F18: {=(SUMPRODUCT(DCF!$G$36:$P$36/(1+F$16)^DCF!$G$40:$P$40)+(DCF!$P$12*(1+Assumptions!$F$28)*(($B18-Assumptions!$Q$46-Assumptions!$Q$47)*(1-Assumptions!$Q$50)+Assumptions!$Q$47-Assumptions!$Q$48)-DCF!$P$12*Assumptions!$F$28*Assumptions!$Q$49)/(F$16-Assumptions!$F$28)/(1+F$16)^Assumptions!$F$27-Assumptions!$F$10+Assumptions!$F$11)/Assumptions!$F$8} -> 181.97344 | G18: {=(SUMPRODUCT(DCF!$G$36:$P$36/(1+G$16)^DCF!$G$40:$P$40)+(DCF!$P$12*(1+Assumptions!$F$28)*(($B18-Assumptions!$Q$46-Assumptions!$Q$47)*(1-Assumptions!$Q$50)+Assumptions!$Q$47-Assumptions!$Q$48)-DCF!$P$12*Assumptions!$F$28*Assumptions!$Q$49)/(G$16-Assumptions!$F$28)/(1+G$16)^Assumptions!$F$27-Assumptions!$F$10+Assumptions!$F$11)/Assumptions!$F$8} -> 156.62427 | H18: {=(SUMPRODUCT(DCF!$G$36:$P$36/(1+H$16)^DCF!$G$40:$P$40)+(DCF!$P$12*(1+Assumptions!$F$28)*(($B18-Assumptions!$Q$46-Assumptions!$Q$47)*(1-Assumptions!$Q$50)+Assumptions!$Q$47-Assumptions!$Q$48)-DCF!$P$12*Assumptions!$F$28*Assumptions!$Q$49)/(H$16-Assumptions!$F$28)/(1+H$16)^Assumptions!$F$27-Assumptions!$F$10+Assumptions!$F$11)/Assumptions!$F$8} -> 137.01831
B19: 0.135 | C19: {=(SUMPRODUCT(DCF!$G$36:$P$36/(1+C$16)^DCF!$G$40:$P$40)+(DCF!$P$12*(1+Assumptions!$F$28)*(($B19-Assumptions!$Q$46-Assumptions!$Q$47)*(1-Assumptions!$Q$50)+Assumptions!$Q$47-Assumptions!$Q$48)-DCF!$P$12*Assumptions!$F$28*Assumptions!$Q$49)/(C$16-Assumptions!$F$28)/(1+C$16)^Assumptions!$F$27-Assumptions!$F$10+Assumptions!$F$11)/Assumptions!$F$8} -> 300.06658 | D19: {=(SUMPRODUCT(DCF!$G$36:$P$36/(1+D$16)^DCF!$G$40:$P$40)+(DCF!$P$12*(1+Assumptions!$F$28)*(($B19-Assumptions!$Q$46-Assumptions!$Q$47)*(1-Assumptions!$Q$50)+Assumptions!$Q$47-Assumptions!$Q$48)-DCF!$P$12*Assumptions!$F$28*Assumptions!$Q$49)/(D$16-Assumptions!$F$28)/(1+D$16)^Assumptions!$F$27-Assumptions!$F$10+Assumptions!$F$11)/Assumptions!$F$8} -> 269.24925 | E19: {=(SUMPRODUCT(DCF!$G$36:$P$36/(1+E$16)^DCF!$G$40:$P$40)+(DCF!$P$12*(1+Assumptions!$F$28)*(($B19-Assumptions!$Q$46-Assumptions!$Q$47)*(1-Assumptions!$Q$50)+Assumptions!$Q$47-Assumptions!$Q$48)-DCF!$P$12*Assumptions!$F$28*Assumptions!$Q$49)/(E$16-Assumptions!$F$28)/(1+E$16)^Assumptions!$F$27-Assumptions!$F$10+Assumptions!$F$11)/Assumptions!$F$8} -> 243.66952 | F19: {=(SUMPRODUCT(DCF!$G$36:$P$36/(1+F$16)^DCF!$G$40:$P$40)+(DCF!$P$12*(1+Assumptions!$F$28)*(($B19-Assumptions!$Q$46-Assumptions!$Q$47)*(1-Assumptions!$Q$50)+Assumptions!$Q$47-Assumptions!$Q$48)-DCF!$P$12*Assumptions!$F$28*Assumptions!$Q$49)/(F$16-Assumptions!$F$28)/(1+F$16)^Assumptions!$F$27-Assumptions!$F$10+Assumptions!$F$11)/Assumptions!$F$8} -> 203.72588 | G19: {=(SUMPRODUCT(DCF!$G$36:$P$36/(1+G$16)^DCF!$G$40:$P$40)+(DCF!$P$12*(1+Assumptions!$F$28)*(($B19-Assumptions!$Q$46-Assumptions!$Q$47)*(1-Assumptions!$Q$50)+Assumptions!$Q$47-Assumptions!$Q$48)-DCF!$P$12*Assumptions!$F$28*Assumptions!$Q$49)/(G$16-Assumptions!$F$28)/(1+G$16)^Assumptions!$F$27-Assumptions!$F$10+Assumptions!$F$11)/Assumptions!$F$8} -> 174.05246 | H19: {=(SUMPRODUCT(DCF!$G$36:$P$36/(1+H$16)^DCF!$G$40:$P$40)+(DCF!$P$12*(1+Assumptions!$F$28)*(($B19-Assumptions!$Q$46-Assumptions!$Q$47)*(1-Assumptions!$Q$50)+Assumptions!$Q$47-Assumptions!$Q$48)-DCF!$P$12*Assumptions!$F$28*Assumptions!$Q$49)/(H$16-Assumptions!$F$28)/(1+H$16)^Assumptions!$F$27-Assumptions!$F$10+Assumptions!$F$11)/Assumptions!$F$8} -> 151.21443
B20: 0.16 | C20: {=(SUMPRODUCT(DCF!$G$36:$P$36/(1+C$16)^DCF!$G$40:$P$40)+(DCF!$P$12*(1+Assumptions!$F$28)*(($B20-Assumptions!$Q$46-Assumptions!$Q$47)*(1-Assumptions!$Q$50)+Assumptions!$Q$47-Assumptions!$Q$48)-DCF!$P$12*Assumptions!$F$28*Assumptions!$Q$49)/(C$16-Assumptions!$F$28)/(1+C$16)^Assumptions!$F$27-Assumptions!$F$10+Assumptions!$F$11)/Assumptions!$F$8} -> 360.74574 | D20: {=(SUMPRODUCT(DCF!$G$36:$P$36/(1+D$16)^DCF!$G$40:$P$40)+(DCF!$P$12*(1+Assumptions!$F$28)*(($B20-Assumptions!$Q$46-Assumptions!$Q$47)*(1-Assumptions!$Q$50)+Assumptions!$Q$47-Assumptions!$Q$48)-DCF!$P$12*Assumptions!$F$28*Assumptions!$Q$49)/(D$16-Assumptions!$F$28)/(1+D$16)^Assumptions!$F$27-Assumptions!$F$10+Assumptions!$F$11)/Assumptions!$F$8} -> 321.98777 | E20: {=(SUMPRODUCT(DCF!$G$36:$P$36/(1+E$16)^DCF!$G$40:$P$40)+(DCF!$P$12*(1+Assumptions!$F$28)*(($B20-Assumptions!$Q$46-Assumptions!$Q$47)*(1-Assumptions!$Q$50)+Assumptions!$Q$47-Assumptions!$Q$48)-DCF!$P$12*Assumptions!$F$28*Assumptions!$Q$49)/(E$16-Assumptions!$F$28)/(1+E$16)^Assumptions!$F$27-Assumptions!$F$10+Assumptions!$F$11)/Assumptions!$F$8} -> 289.89781 | F20: {=(SUMPRODUCT(DCF!$G$36:$P$36/(1+F$16)^DCF!$G$40:$P$40)+(DCF!$P$12*(1+Assumptions!$F$28)*(($B20-Assumptions!$Q$46-Assumptions!$Q$47)*(1-Assumptions!$Q$50)+Assumptions!$Q$47-Assumptions!$Q$48)-DCF!$P$12*Assumptions!$F$28*Assumptions!$Q$49)/(F$16-Assumptions!$F$28)/(1+F$16)^Assumptions!$F$27-Assumptions!$F$10+Assumptions!$F$11)/Assumptions!$F$8} -> 239.97996 | G20: {=(SUMPRODUCT(DCF!$G$36:$P$36/(1+G$16)^DCF!$G$40:$P$40)+(DCF!$P$12*(1+Assumptions!$F$28)*(($B20-Assumptions!$Q$46-Assumptions!$Q$47)*(1-Assumptions!$Q$50)+Assumptions!$Q$47-Assumptions!$Q$48)-DCF!$P$12*Assumptions!$F$28*Assumptions!$Q$49)/(G$16-Assumptions!$F$28)/(1+G$16)^Assumptions!$F$27-Assumptions!$F$10+Assumptions!$F$11)/Assumptions!$F$8} -> 203.09943 | H20: {=(SUMPRODUCT(DCF!$G$36:$P$36/(1+H$16)^DCF!$G$40:$P$40)+(DCF!$P$12*(1+Assumptions!$F$28)*(($B20-Assumptions!$Q$46-Assumptions!$Q$47)*(1-Assumptions!$Q$50)+Assumptions!$Q$47-Assumptions!$Q$48)-DCF!$P$12*Assumptions!$F$28*Assumptions!$Q$49)/(H$16-Assumptions!$F$28)/(1+H$16)^Assumptions!$F$27-Assumptions!$F$10+Assumptions!$F$11)/Assumptions!$F$8} -> 174.87463
B21: 0.2 | C21: {=(SUMPRODUCT(DCF!$G$36:$P$36/(1+C$16)^DCF!$G$40:$P$40)+(DCF!$P$12*(1+Assumptions!$F$28)*(($B21-Assumptions!$Q$46-Assumptions!$Q$47)*(1-Assumptions!$Q$50)+Assumptions!$Q$47-Assumptions!$Q$48)-DCF!$P$12*Assumptions!$F$28*Assumptions!$Q$49)/(C$16-Assumptions!$F$28)/(1+C$16)^Assumptions!$F$27-Assumptions!$F$10+Assumptions!$F$11)/Assumptions!$F$8} -> 457.83239 | D21: {=(SUMPRODUCT(DCF!$G$36:$P$36/(1+D$16)^DCF!$G$40:$P$40)+(DCF!$P$12*(1+Assumptions!$F$28)*(($B21-Assumptions!$Q$46-Assumptions!$Q$47)*(1-Assumptions!$Q$50)+Assumptions!$Q$47-Assumptions!$Q$48)-DCF!$P$12*Assumptions!$F$28*Assumptions!$Q$49)/(D$16-Assumptions!$F$28)/(1+D$16)^Assumptions!$F$27-Assumptions!$F$10+Assumptions!$F$11)/Assumptions!$F$8} -> 406.36941 | E21: {=(SUMPRODUCT(DCF!$G$36:$P$36/(1+E$16)^DCF!$G$40:$P$40)+(DCF!$P$12*(1+Assumptions!$F$28)*(($B21-Assumptions!$Q$46-Assumptions!$Q$47)*(1-Assumptions!$Q$50)+Assumptions!$Q$47-Assumptions!$Q$48)-DCF!$P$12*Assumptions!$F$28*Assumptions!$Q$49)/(E$16-Assumptions!$F$28)/(1+E$16)^Assumptions!$F$27-Assumptions!$F$10+Assumptions!$F$11)/Assumptions!$F$8} -> 363.86308 | F21: {=(SUMPRODUCT(DCF!$G$36:$P$36/(1+F$16)^DCF!$G$40:$P$40)+(DCF!$P$12*(1+Assumptions!$F$28)*(($B21-Assumptions!$Q$46-Assumptions!$Q$47)*(1-Assumptions!$Q$50)+Assumptions!$Q$47-Assumptions!$Q$48)-DCF!$P$12*Assumptions!$F$28*Assumptions!$Q$49)/(F$16-Assumptions!$F$28)/(1+F$16)^Assumptions!$F$27-Assumptions!$F$10+Assumptions!$F$11)/Assumptions!$F$8} -> 297.98648 | G21: {=(SUMPRODUCT(DCF!$G$36:$P$36/(1+G$16)^DCF!$G$40:$P$40)+(DCF!$P$12*(1+Assumptions!$F$28)*(($B21-Assumptions!$Q$46-Assumptions!$Q$47)*(1-Assumptions!$Q$50)+Assumptions!$Q$47-Assumptions!$Q$48)-DCF!$P$12*Assumptions!$F$28*Assumptions!$Q$49)/(G$16-Assumptions!$F$28)/(1+G$16)^Assumptions!$F$27-Assumptions!$F$10+Assumptions!$F$11)/Assumptions!$F$8} -> 249.57458 | H21: {=(SUMPRODUCT(DCF!$G$36:$P$36/(1+H$16)^DCF!$G$40:$P$40)+(DCF!$P$12*(1+Assumptions!$F$28)*(($B21-Assumptions!$Q$46-Assumptions!$Q$47)*(1-Assumptions!$Q$50)+Assumptions!$Q$47-Assumptions!$Q$48)-DCF!$P$12*Assumptions!$F$28*Assumptions!$Q$49)/(H$16-Assumptions!$F$28)/(1+H$16)^Assumptions!$F$27-Assumptions!$F$10+Assumptions!$F$11)/Assumptions!$F$8} -> 212.73095
A23: INTERPRETATION
A24: • Current market price of ₹251 implies long-run EBITDA margin >18% AND/OR terminal growth >7%, OR a lower WACC than modelled.
A25: • Base case (WACC 13.02%, g 5.00%, term margin 13.4%) implies ₹88/share — significantly below market.
A26: • Use Assumptions!F15:F17 to flex WACC inputs; G32:Q43 to flex segment growth and margin paths.

Sheet Balance Sheet
A1: Eternal Limited (formerly Zomato Limited) — Consolidated Balance Sheet
A2: As at March 31 of each fiscal year. All values in INR crores (1 crore = 10 million).
A4: Particulars | B4: ₹ Cr | C4: FY22 | D4: FY23 | E4: FY24 | F4: FY25
A5: ASSETS
A6: Non-current assets
A7: Property, plant and equipment | B7: ₹ Cr | C7: 50.9 | D7: 208.5 | E7: 287 | F7: 965
A8: Capital work-in-progress | B8: ₹ Cr | C8: 0.6 | D8: 7.5 | E8: 18 | F8: 51
A9: Right-of-use assets | B9: ₹ Cr | C9: 64.2 | D9: 427.2 | E9: 690 | F9: 1918
